<?xml version="1.0"?>

<robot xmlns:xacro="http://www.ros.org/wiki/xacro" name="mors_sim">

  <xacro:include filename="$(find mors_sim)/urdf/materials.xacro"/>
  <xacro:include filename="$(find mors_sim)/urdf/mors_gazebo.xacro"/>
  <xacro:include filename="$(find mors_sim)/urdf/d435.xacro"/>
  <xacro:include filename="$(find mors_sim)/urdf/rplidar_a1.xacro"/>

    <xacro:property name="PI" value="3.1415926535897931"/>

    <!-- Meshes Address-->
    <xacro:property name="mesh_addr" value="package://mors_sim/urdf/meshes/"/>

    <!-- Mass parameters-->
    <xacro:property name="body_mass" value="3.659"/>
    <xacro:property name="abad_mass" value="0.309"/>
    <xacro:property name="hip_mass" value="0.532"/>
    <xacro:property name="knee_mass" value="0.049"/>

    <!-- CoG Parameters -->
    <xacro:property name="body_cog_x" value="-0.00272"/>
    <xacro:property name="body_cog_y" value="0.000875"/>
    <xacro:property name="body_cog_z" value="0.000178"/>
    <xacro:property name="abad_cog_x" value="-0.00606"/>
    <xacro:property name="abad_cog_y" value="-0.000018"/>
    <xacro:property name="abad_cog_z" value="0.058144"/>
    <xacro:property name="hip_cog_x" value="0.034385"/>
    <xacro:property name="hip_cog_y" value="-0.000226"/>
    <xacro:property name="hip_cog_z" value="0.044820"/>
    <xacro:property name="knee_cog_x" value="0.058408"/>
    <xacro:property name="knee_cog_y" value="0.0"/>
    <xacro:property name="knee_cog_z" value="0.009288"/>

    <!-- Inertia -->
    <xacro:property name="body_ixx" value="0.012838176"/>
    <xacro:property name="body_ixy" value="-0.000006851"/>
    <xacro:property name="body_ixz" value="0.000156493"/>
    <xacro:property name="body_iyy" value="0.056852389"/>
    <xacro:property name="body_iyz" value="-0.000095392"/>
    <xacro:property name="body_izz" value="0.064034355"/>
    <xacro:property name="abad_ixx" value="0.000178705"/>
    <xacro:property name="abad_ixy" value="-1.02e-7"/>
    <xacro:property name="abad_ixz" value="-0.000003483"/>
    <xacro:property name="abad_iyy" value="0.000161337"/>
    <xacro:property name="abad_iyz" value="-5e-9"/>
    <xacro:property name="abad_izz" value="0.0001003"/>
    <xacro:property name="hip_ixx" value="0.000279734"/>
    <xacro:property name="hip_ixy" value="2.8e-7"/>
    <xacro:property name="hip_ixz" value="-0.000253770"/>
    <xacro:property name="hip_iyy" value="0.001715204"/>
    <xacro:property name="hip_iyz" value="-1.2e-6"/>
    <xacro:property name="hip_izz" value="0.001731949"/>
    <xacro:property name="knee_ixx" value="0.000003796"/>
    <xacro:property name="knee_ixy" value="0.0"/>
    <xacro:property name="knee_ixz" value="-0.000007744"/>
    <xacro:property name="knee_iyy" value="0.000208824"/>
    <xacro:property name="knee_iyz" value="0.0"/>
    <xacro:property name="knee_izz" value="0.000208730"/>

    <!-- Joints parameters-->
    <xacro:property name="velocity_max" value="10.6"/>
    <xacro:property name="torque_max" value="2000"/>
    <xacro:property name="damping" value="0.8"/>
    <xacro:property name="friction" value="0"/>
    <xacro:property name="theta_max" value="150"/>
    <xacro:property name="theta_min" value="-150"/>

    <!-- Leg parts attachment positions to the body-->
    <xacro:property name="abad_attach_x" value="0.1035"/>
    <xacro:property name="abad_attach_y" value="0.066"/>
    <xacro:property name="abad_attach_z" value="0.0"/>
    <xacro:property name="hip_attach_x" value="0.0105"/>
    <xacro:property name="hip_attach_y" value="0.0"/>
    <xacro:property name="hip_attach_z" value="0.059"/>
    <xacro:property name="knee_attach_x" value="0.13"/>
    <xacro:property name="knee_attach_y" value="0.0"/>
    <xacro:property name="knee_attach_z" value="0.07335"/>
    <xacro:property name="ef_attach_x" value="0.1485"/>
    <xacro:property name="ef_attach_y" value="0.0"/>
    <xacro:property name="ef_attach_z" value="0.012"/>

    <xacro:macro name="default_inertial" params="mass ixx ixy ixz iyy iyz izz">
      <inertial>
        <mass value="${mass}"/>
        <inertia ixx="${ixx}" ixy="${ixy}" ixz="${ixz}"
          iyy="${iyy}" iyz="${iyz}"
          izz="${izz}" />
      </inertial>
    </xacro:macro>

  <!-- body -->
    <link name="base_link">
      <visual>
        <geometry>
          <mesh filename="${mesh_addr}body.stl" scale="1 1 1"/>
        </geometry>
        <origin rpy="0 0 0" xyz="0 0 0"/>
        <material name="silver"/>
      </visual>
      <collision>
        <origin rpy="0 0 0" xyz="0 0 0"/>
        <geometry>
          <mesh filename="${mesh_addr}body.stl" scale="1 1 1"/>
        </geometry>
      </collision>
    </link>

    <link name="base_inertia">
      <inertial>
        <origin rpy="0 0 0" xyz="${body_cog_x} ${body_cog_y} ${body_cog_z}"/>
        <mass value="${body_mass}"/>
        <inertia ixx="${body_ixx}" ixy="${body_ixy}" ixz="${body_ixz}"
          iyy="${body_iyy}" iyz="${body_iyz}"
          izz="${body_izz}" />
      </inertial>
    </link>
    <joint name="base_link_to_base_inertia" type="fixed">
        <parent link="base_link"/>
        <child link="base_inertia"/>
        <origin rpy="0 0 0" xyz="0 0 0"/>
    </joint>

  <!-- Script for building a leg-->
  <xacro:macro name="leg" params="side num x y sh_x_angle sh_y_angle sh_z_angle abad_angle_dir hip_sign">
    
    <!-- abad -->
    <joint name="abad_joint_${side}${num}" type="revolute">
      <parent link="base_link"/>
      <child link="abad_${side}${num}"/>
      <origin rpy="${sh_x_angle} ${sh_y_angle} ${sh_z_angle}" xyz="${x} ${y} ${abad_attach_z}"/>
      <axis xyz="0 0 ${abad_angle_dir}"/>
      <dynamics damping="${damping}" friction="${friction}"/>
      <limit effort="${torque_max}" velocity="${velocity_max}" lower="${theta_max*PI/180.0}" upper="${theta_min*PI/180.0}"/>
    </joint>

    <link name="abad_${side}${num}">
      <visual>
        <origin rpy="0 0 0" xyz="0 0 0"/>
        <geometry>
          <mesh filename="${mesh_addr}joint1.stl" scale="1 1 1"/>
        </geometry>
        <material name="white_blue"/>
      </visual>
      <collision>
        <origin rpy="0 0 0" xyz="0 0 0"/>
        <geometry>
          <mesh filename="${mesh_addr}joint1.stl" scale="1 1 1"/>
        </geometry>
      </collision>
      <inertial>
        <origin rpy="0 0 1.57" xyz="${abad_cog_x} ${abad_cog_y} ${abad_cog_z}"/>
        <mass value="${abad_mass}"/>
        <inertia ixx="${abad_ixx}" ixy="${abad_ixy}" ixz="${abad_ixz}"
          iyy="${abad_iyy}" iyz="${abad_iyz}"
          izz="${abad_izz}" />
      </inertial>
    </link>

    <!-- Hip-->
    <joint name="hip_joint_${side}${num}" type="revolute">
      <parent link="abad_${side}${num}"/>
      <child link="hip_${side}${num}"/>
      <origin rpy="${hip_sign*PI/2} ${-hip_sign*0*PI/2} ${hip_sign*PI/2}" xyz="${hip_attach_x} ${hip_attach_y} ${hip_attach_z}"/>
      <axis xyz="0 0 1"/>
      <dynamics damping="${damping}" friction="${friction}"/>
      <limit effort="${torque_max}" velocity="${velocity_max}" lower="${theta_max*PI/180.0}" upper="${theta_min*PI/180.0}"/>
    </joint>

    <link name="hip_${side}${num}">
      <visual>
        <origin rpy="0 0 0" xyz="0 0 0"/>
        <geometry>
          <mesh filename="${mesh_addr}joint2.stl" scale="1 1 1"/>
        </geometry>
        <material name="silver"/>
      </visual>
      <collision>
        <geometry>
          <mesh filename="${mesh_addr}joint2.stl" scale="1 1 1"/>
        </geometry>
      </collision>
      <inertial>
        <origin rpy="0 0 0" xyz="${hip_cog_x} ${hip_cog_y} ${hip_cog_z}"/>
        <mass value="${hip_mass}"/>
        <inertia ixx="${hip_ixx}" ixy="${hip_ixy}" ixz="${hip_ixz}"
          iyy="${hip_iyy}" iyz="${hip_iyz}"
          izz="${hip_izz}" />
      </inertial>
    </link>

    <!-- Knee -->
    <joint name="knee_joint_${side}${num}" type="revolute">
      <parent link="hip_${side}${num}"/>
      <child link="knee_${side}${num}"/>
      <origin rpy="${PI} ${PI} ${PI}" xyz="${knee_attach_x} ${knee_attach_y} ${knee_attach_z}"/>
      <axis xyz="0 0 1"/>
      <dynamics damping="${damping}" friction="${friction}"/>
      <limit effort="${torque_max}" velocity="${velocity_max}" lower="${theta_max*PI/180.0}" upper="${theta_min*PI/180.0}"/>
    </joint>

    <link name="knee_${side}${num}">
      <visual>
        <origin rpy="0 0 0" xyz="0 0 0"/>
        <geometry>
          <mesh filename="${mesh_addr}joint3_1.stl" scale="1 1 1"/>
        </geometry>
        <material name="white_blue"/>
      </visual>
      <collision>
        <geometry>
          <mesh filename="${mesh_addr}joint3_1.stl" scale="1 1 1"/>
        </geometry>
      </collision>
      <inertial>
        <origin rpy="0 0 0" xyz="${knee_cog_x} ${knee_cog_y} ${knee_cog_z}"/>
        <mass value="${knee_mass}"/>
        <inertia ixx="${knee_ixx}" ixy="${knee_ixy}" ixz="${knee_ixz}"
          iyy="${knee_iyy}" iyz="${knee_iyz}"
          izz="${knee_izz}" />
      </inertial>
    </link>

    <link name="ef_${side}${num}"> 
    <visual>
      <origin rpy="0 0 0" xyz="0 0 0"/>
      <geometry>
        <mesh filename="${mesh_addr}joint3_2.stl" scale="1 1 1"/>
      </geometry>
      <material name="white_blue"/>
    </visual>
    <collision>
      <geometry>
        <mesh filename="${mesh_addr}joint3_2.stl" scale="1 1 1"/>
      </geometry>
    </collision>
    <!-- <inertial>
        <origin rpy="0 0 -0.896" xyz="0 0 0"/>
        <mass value="0.04"/>
        <inertia ixx="0.00000105" ixy="0" ixz="0"
          iyy="0.00000105" iyz="0"
          izz="0.000001149" />
      </inertial> -->
    </link>

    <!-- End Effector-->
    <joint name="ef_joint_${side}${num}" type="fixed">
      <parent link="knee_${side}${num}"/>
      <child link="ef_${side}${num}"/>
      <origin rpy="0 0 0" xyz="${ef_attach_x} ${ef_attach_y} ${ef_attach_z}"/>
    </joint>

    <!-- Define actuators -->
		<transmission name="abad_transmission_${side}${num}">
			<type>transmission_interface/SimpleTransmission</type>
			<joint name="abad_joint_${side}${num}">
				<hardwareInterface>hardware_interface/EffortJointInterface</hardwareInterface>
			</joint>
			<actuator name="soulder_motor_${side}${num}">
				<hardwareInterface>hardware_interface/EffortJointInterface</hardwareInterface>
				<mechanicalReduction>1.0</mechanicalReduction>
				<motorTorqueConstant>1.0</motorTorqueConstant>
			</actuator>
		</transmission>

		<transmission name="hip_transmission_${side}${num}">
			<type>transmission_interface/SimpleTransmission</type>
			<joint name="hip_joint_${side}${num}">
				<hardwareInterface>hardware_interface/EffortJointInterface</hardwareInterface>
			</joint>
			<actuator name="hip_motor_${side}${num}">
				<hardwareInterface>hardware_interface/EffortJointInterface</hardwareInterface>
				<mechanicalReduction>1.0</mechanicalReduction>
				<motorTorqueConstant>1.0</motorTorqueConstant>
			</actuator>
		</transmission>

		<transmission name="knee_transmission_${side}${num}">
			<type>transmission_interface/SimpleTransmission</type>
			<joint name="knee_joint_${side}${num}">
				<hardwareInterface>hardware_interface/EffortJointInterface</hardwareInterface>
			</joint>
			<actuator name="knee_motor_${side}${num}">
				<hardwareInterface>hardware_interface/EffortJointInterface</hardwareInterface>
				<mechanicalReduction>1.0</mechanicalReduction>
				<motorTorqueConstant>1.0</motorTorqueConstant>
			</actuator>
		</transmission>

  </xacro:macro>

  <xacro:leg side="R" num="1" x="${abad_attach_x}" y="${-abad_attach_y}" sh_x_angle="${radians(-90)}" sh_y_angle="${radians(0)}" sh_z_angle="${radians(-90)}" abad_angle_dir="1" hip_sign="1"/>
  <xacro:leg side="R" num="2" x="${-abad_attach_x}" y="${-abad_attach_y}" sh_x_angle="${radians(90)}" sh_y_angle="${radians(0)}" sh_z_angle="${radians(-90)}" abad_angle_dir="1" hip_sign="-1"/>
  <xacro:leg side="L" num="1" x="${abad_attach_x}" y="${abad_attach_y}" sh_x_angle="${radians(90)}" sh_y_angle="${radians(0)}" sh_z_angle="${radians(90)}" abad_angle_dir="1" hip_sign="-1"/>
  <xacro:leg side="L" num="2" x="${-abad_attach_x}" y="${abad_attach_y}" sh_x_angle="${radians(-90)}" sh_y_angle="${radians(0)}" sh_z_angle="${radians(90)}" abad_angle_dir="1" hip_sign="1"/>

  <joint name="camera_joint" type="fixed">
    <origin rpy="0 0 0" xyz="0.238 0.0 0.0"/>
    <parent link="base_link"/>
    <child link="camera_frame" />
  </joint>
  <link name="camera_frame">
    <inertial>
      <origin rpy="0 0 0" xyz="0 0 0"/>
      <mass value="0.1"/>
      <inertia ixx="0.001" ixy="0" ixz="0"
        iyy="0.001" iyz="0"
        izz="0.001" />
    </inertial>
  </link>

  <xacro:rplidar_a1 name="scan" topics_ns="scan" parent="base_link">
    <origin rpy="0 0 0" xyz="0.15 0.0 0.115"/>
  </xacro:rplidar_a1> 

  <link name="imu_link">
    <inertial>
      <mass value="0.001"/>
      <origin rpy="0 0 0" xyz="0 0 0"/>
      <inertia ixx="1e-09" ixy="0.0" ixz="0.0" iyy="1e-09" iyz="0.0" izz="1e-09"/>
    </inertial>
  </link>
  <joint name="imu_joint" type="fixed">
    <parent link="base_link"/>
    <child link="imu_link"/>
  </joint>

</robot>
