<?xml version="1.0"?>
<!-- =================================================================================== -->
<!-- |    This document was autogenerated by xacro from walkerbro.xacro                | -->
<!-- |    EDITING THIS FILE BY HAND IS NOT RECOMMENDED                                 | -->
<!-- =================================================================================== -->
<robot name="walkerbro_sim"  xmlns:xacro="http://ros.org/wiki/xacro">
  <xacro:property name="abad_length" value="0.09885"/>
  <xacro:property name="hip_length" value="0.13"/>
  <xacro:property name="shank_length" value="0.156"/>

  <xacro:property name="abad_mass" value="0.301"/>
  <xacro:property name="hip_mass" value="0.604"/>
  <xacro:property name="shank_mass" value="0.0408"/>

  <material name="black">
    <color rgba="0.0 0.0 0.0 1.0"/>
  </material>
  <material name="blue">
    <color rgba="0.0 0.0 0.8 1.0"/>
  </material>
  <material name="green">
    <color rgba="0.0 0.8 0.0 1.0"/>
  </material>
  <material name="grey">
    <color rgba="0.2 0.2 0.2 1.0"/>
  </material>
  <material name="silver">
    <color rgba="0.9137254901960784 0.9137254901960784 0.8470588235294118 1.0"/>
  </material>
  <material name="orange">
    <color rgba="1.0 0.4235294117647059 0.0392156862745098 1.0"/>
  </material>
  <material name="brown">
    <color rgba="0.8705882352941177 0.8117647058823529 0.7647058823529411 1.0"/>
  </material>
  <material name="white_gray">
    <color rgba="0.8235294117647058 0.8235294117647058 0.8235294117647058 1.0"/>
  </material>
  <material name="gold">
    <color rgba="0.8117647058823529 0.6784313725490196 0.30196078431372547 1.0"/>
  </material>
  <material name="white_blue">
    <color rgba="0.4627450980392157 0.8 0.9921568627450981 1.0"/>
  </material>
  <material name="white_black">
    <color rgba="0.49411764705882355 0.49411764705882355 0.49411764705882355 1.0"/>
  </material>
  <material name="red">
    <color rgba="0.8 0.0 0.0 1.0"/>
  </material>
  <material name="white">
    <color rgba="1.0 1.0 1.0 1.0"/>
  </material>
  <!-- ros_control plugin -->
  <gazebo>
    <plugin filename="libgazebo_ros_control.so" name="gazebo_ros_control">
      <robotNamespace>/quadro_main</robotNamespace>
      <robotSimType>gazebo_ros_control/DefaultRobotHWSim</robotSimType>
    </plugin>
  </gazebo>
  <!-- Show the trajectory of trunk center. -->
  <!-- <gazebo>
                <plugin name="3dplot" filename="libLinkPlot3DPlugin.so">
                        <frequency>10</frequency>
                        <plot>
                                <link>knee_R1</link>
                                <pose>0 -0.176295 0 0 0 0</pose>
                                <material>Gazebo/Yellow</material>
                        </plot>
                </plugin>
        </gazebo> -->
  <!-- Body Link -->
  <gazebo reference="base_link">
    <mu1>0.9</mu1>
    <mu2>0.9</mu2>
    <kp value="1000000.0"/>
    <kd value="1.0"/>
    <material>Gazebo/Grey</material>
  </gazebo>
  <!-- Shoulder R1 -->
  <gazebo reference="abad_R1">
    <kp>1000000.0</kp>
    <kd>1.0</kd>
    <mu1>0.9</mu1>
    <mu2>0.9</mu2>
    <fdir1>1 1 0</fdir1>
    <minDepth>0.001</minDepth>
    <self_collide>true</self_collide>
    <max_vel>0.1</max_vel>
    <material>Gazebo/DarkGrey</material>
  </gazebo>
  <!-- hip R1 -->
  <gazebo reference="hip_R1">
    <kp>1000000.0</kp>
    <kd>1.0</kd>
    <mu1>0.9</mu1>
    <mu2>0.9</mu2>
    <fdir1>1 1 0</fdir1>
    <minDepth>0.001</minDepth>
    <self_collide>true</self_collide>
    <max_vel>0.1</max_vel>
    <material>Gazebo/DarkGrey</material>
  </gazebo>
  <!-- knee R1 -->
  <gazebo reference="knee_R1">
    <kp>1000000.0</kp>
    <kd>1.0</kd>
    <mu1>0.9</mu1>
    <mu2>0.9</mu2>
    <fdir1>1 1 0</fdir1>
    <minDepth>0.001</minDepth>
    <self_collide>true</self_collide>
    <max_vel>0.1</max_vel>
    <material>Gazebo/DarkGrey</material>
  </gazebo>
  <!-- shoulder R2 -->
  <gazebo reference="abad_R2">
    <kp>1000000.0</kp>
    <kd>1.0</kd>
    <mu1>0.9</mu1>
    <mu2>0.9</mu2>
    <fdir1>1 1 0</fdir1>
    <minDepth>0.001</minDepth>
    <self_collide>true</self_collide>
    <max_vel>0.1</max_vel>
    <material>Gazebo/DarkGrey</material>
  </gazebo>
  <!-- hip R2 -->
  <gazebo reference="hip_R2">
    <kp>1000000.0</kp>
    <kd>1.0</kd>
    <mu1>0.9</mu1>
    <mu2>0.9</mu2>
    <fdir1>1 1 0</fdir1>
    <minDepth>0.001</minDepth>
    <self_collide>true</self_collide>
    <max_vel>0.1</max_vel>
    <material>Gazebo/DarkGrey</material>
  </gazebo>
  <!-- knee R2 -->
  <gazebo reference="knee_R2">
    <kp>1000000.0</kp>
    <kd>1.0</kd>
    <mu1>1000.9</mu1>
    <mu2>1000.9</mu2>
    <fdir1>1 1 0</fdir1>
    <minDepth>0.001</minDepth>
    <self_collide>true</self_collide>
    <max_vel>0.1</max_vel>
    <material>Gazebo/DarkGrey</material>
  </gazebo>
  <!-- - - - - - - - - - - - - - - -->
  <!-- shoulder L1 -->
  <gazebo reference="abad_L1">
    <kp>1000000.0</kp>
    <kd>1.0</kd>
    <mu1>0.9</mu1>
    <mu2>0.9</mu2>
    <fdir1>1 1 0</fdir1>
    <minDepth>0.001</minDepth>
    <self_collide>true</self_collide>
    <max_vel>0.1</max_vel>
    <material>Gazebo/DarkGrey</material>
  </gazebo>
  <!-- hip L1 -->
  <gazebo reference="hip_L1">
    <kp>1000000.0</kp>
    <kd>1.0</kd>
    <mu1>0.9</mu1>
    <mu2>0.9</mu2>
    <fdir1>1 1 0</fdir1>
    <minDepth>0.001</minDepth>
    <self_collide>true</self_collide>
    <max_vel>0.1</max_vel>
    <material>Gazebo/DarkGrey</material>
  </gazebo>
  <!-- knee L1 -->
  <gazebo reference="knee_L1">
    <kp>1000000.0</kp>
    <kd>1.0</kd>
    <mu1>1000.9</mu1>
    <mu2>1000.9</mu2>
    <fdir1>1 1 0</fdir1>
    <minDepth>0.001</minDepth>
    <self_collide>true</self_collide>
    <max_vel>0.1</max_vel>
    <material>Gazebo/DarkGrey</material>
  </gazebo>
  <!-- shoulder L2 -->
  <gazebo reference="abad_L2">
    <kp>1000000.0</kp>
    <kd>1.0</kd>
    <mu1>0.9</mu1>
    <mu2>0.9</mu2>
    <fdir1>1 1 0</fdir1>
    <minDepth>0.001</minDepth>
    <self_collide>true</self_collide>
    <max_vel>0.1</max_vel>
    <material>Gazebo/DarkGrey</material>
  </gazebo>
  <!-- hip L2 -->
  <gazebo reference="hip_L2">
    <kp>1000000.0</kp>
    <kd>1.0</kd>
    <mu1>0.9</mu1>
    <mu2>0.9</mu2>
    <fdir1>1 1 0</fdir1>
    <minDepth>0.001</minDepth>
    <self_collide>true</self_collide>
    <max_vel>0.1</max_vel>
    <material>Gazebo/DarkGrey</material>
  </gazebo>
  <!-- knee L2 -->
  <gazebo reference="knee_L2">
    <kp>1000000.0</kp>
    <kd>1.0</kd>
    <mu1>0.9</mu1>
    <mu2>0.9</mu2>
    <fdir1>1 1 0</fdir1>
    <minDepth>0.001</minDepth>
    <self_collide>true</self_collide>
    <max_vel>0.1</max_vel>
    <material>Gazebo/DarkGrey</material>
  </gazebo>
  <!-- <link name="base_link" />

    <joint name="base_joint" type="fixed">
      <parent link="base_link" />
      <child link="body" />
      <origin xyz="0 0 0" rpy="0 0 0" />
    </joint> -->
  <!-- body -->
  <link name="base_link">
    <visual>
      <geometry>
        <mesh filename="package://walkerbro_sim/urdf/meshes_for_nav/body.stl" scale="1 1 1"/>
      </geometry>
      <origin rpy="0 0 0" xyz="0 0 0"/>
      <material name="silver"/>
    </visual>
    <collision>
      <origin rpy="0 0 0" xyz="0 0 0"/>
      <geometry>
        <mesh filename="package://walkerbro_sim/urdf/meshes_for_nav/body.stl" scale="1 1 1"/>
      </geometry>
    </collision>
    <!-- <inertial>
        <origin rpy="0 0 0" xyz="${body_cog_x} ${body_cog_y} ${body_cog_z}"/>
        <mass value="${body_mass}"/>
        <inertia ixx="${body_ixx}" ixy="${body_ixy}" ixz="${body_ixz}"
          iyy="${body_iyy}" iyz="${body_iyz}"
          izz="${body_izz}" />
      </inertial> -->
  </link>
  <link name="base_inertia">
    <inertial>
      <origin rpy="0 0 0" xyz="0 0 0"/>
      <mass value="3.96"/>
      <inertia ixx="0.010465897" ixy="1.6827e-05" ixz="5.084e-05" iyy="0.041761318" iyz="-1.0593e-05" izz="0.047418719"/>
    </inertial>
  </link>
  <joint name="base_link_to_base_inertia" type="fixed">
    <parent link="base_link"/>
    <child link="base_inertia"/>
    <origin rpy="0 0 0" xyz="0 0 0"/>
  </joint>
  <!-- <joint name="camera_joint" type="fixed">
      <origin rpy="0 0 0" xyz="0.25 0.0 0.0"/>
      <parent link="base_joint"/>
      <child link="camera_link"/>
    </joint> -->
  <!-- abad -->
  <joint name="abad_joint_R1" type="revolute">
    <parent link="base_link"/>
    <child link="abad_R1"/>
    <origin rpy="0 0 0" xyz="0.149 -0.066 0.0"/>
    <axis xyz="1 0 0"/>
    <dynamics damping="0.8" friction="0"/>
    <limit effort="25" lower="2.6179938779914944" upper="-2.6179938779914944" velocity="1.5"/>
  </joint>
  <link name="abad_R1">
    <visual>
      <origin rpy="1.57 3.14 1.57" xyz="-0.046 0.0 0.0"/>
      <geometry>
        <mesh filename="package://walkerbro_sim/urdf/meshes_for_nav/joint1.stl" scale="1 1 1"/>
      </geometry>
      <material name="white_blue"/>
    </visual>
    <collision>
      <origin rpy="1.57 3.14 1.57" xyz="-0.046 0.0 0.0"/>
      <geometry>
        <mesh filename="package://walkerbro_sim/urdf/meshes_for_nav/joint1.stl" scale="1 1 1"/>
      </geometry>
    </collision>
    <inertial>
      <origin rpy="1.57 3.14 1.57" xyz="-0.046 0.0 0.0"/>
      <mass value="0.301"/>
      <inertia ixx="0.000184443" ixy="-1.02e-07" ixz="-3.776e-06" iyy="0.000166614" iyz="-1e-08" izz="9.0598e-05"/>
    </inertial>
  </link>
  <!-- Hip-->
  <joint name="hip_joint_R1" type="revolute">
    <parent link="abad_R1"/>
    <child link="hip_R1"/>
    <origin rpy="0 0 0" xyz="0.0 ${-abad_length} 0.0"/>
    <axis xyz="0 1 0"/>
    <dynamics damping="0.8" friction="0"/>
    <limit effort="2000" lower="2.6179938779914944" upper="-2.6179938779914944" velocity="10.6"/>
  </joint>
  <link name="hip_R1">
    <visual>
      <origin rpy="1.57 1.57 0.0" xyz="0.0 0.08835 0.0"/>
      <geometry>
        <mesh filename="package://walkerbro_sim/urdf/meshes/joint2.stl" scale="1 1 1"/>
      </geometry>
      <material name="silver"/>
    </visual>
    <collision>
      <geometry>
        <mesh filename="package://walkerbro_sim/urdf/meshes/joint2.stl" scale="1 1 1"/>
      </geometry>
      <origin rpy="1.57 1.57 0.0" xyz="0.0 0.08835 0.0"/>
    </collision>
    <inertial>
      <origin rpy="1.57 1.57 0.0" xyz="0.0 0.08835 0.0"/>
      <mass value="0.503"/>
      <inertia ixx="0.00027565" ixy="1.96e-07" ixz="-0.000196226" iyy="0.001115802" iyz="4.8e-08" izz="0.001123233"/>
    </inertial>
  </link>
  <!-- Knee -->
  <joint name="knee_joint_R1" type="revolute">
    <parent link="hip_R1"/>
    <child link="knee_R1"/>
    <origin rpy="0.0 0 0.0" xyz="0.0 0.0 -0.104"/>
    <axis xyz="0 1 0"/>
    <dynamics damping="0.8" friction="0"/>
    <limit effort="2000" lower="2.6179938779914944" upper="-2.6179938779914944" velocity="10.6"/>
  </joint>
  <link name="knee_R1">
    <visual>
      <origin rpy="1.57 1.57 0.0" xyz="0.0 0.012 0.0"/>
      <geometry>
        <mesh filename="package://walkerbro_sim/urdf/meshes/joint3.stl" scale="1 1 1"/>
      </geometry>
      <material name="white_blue"/>
    </visual>
    <collision>
      <geometry>
        <mesh filename="package://walkerbro_sim/urdf/meshes/joint3.stl" scale="1 1 1"/>
      </geometry>
      <origin rpy="1.57 1.57 0.0" xyz="0.0 0.012 0.0"/>
    </collision>
    <inertial>
      <origin rpy="1.57 1.57 0.0" xyz="0.0 0.012 0.0"/>
      <mass value="0.044"/>
      <inertia ixx="3.607e-06" ixy="0.0" ixz="-5.707e-06" iyy="0.000115918" iyz="0.0" izz="0.000115863"/>
    </inertial>
  </link>
  <!-- End Effector-->
  <joint name="ef_joint_R1" type="fixed">
    <parent link="knee_R1"/>
    <child link="ef_R1"/>
    <origin xyz="0 0 -0.1125"/>
  </joint>
  <link name="ef_R1"/>
  <!-- Define actuators -->
  <transmission name="abad_transmission_R1">
    <type>transmission_interface/SimpleTransmission</type>
    <joint name="abad_joint_R1">
      <hardwareInterface>hardware_interface/EffortJointInterface</hardwareInterface>
    </joint>
    <actuator name="soulder_motor_R1">
      <hardwareInterface>hardware_interface/EffortJointInterface</hardwareInterface>
      <mechanicalReduction>1.0</mechanicalReduction>
      <motorTorqueConstant>1.0</motorTorqueConstant>
    </actuator>
  </transmission>
  <transmission name="hip_transmission_R1">
    <type>transmission_interface/SimpleTransmission</type>
    <joint name="hip_joint_R1">
      <hardwareInterface>hardware_interface/EffortJointInterface</hardwareInterface>
    </joint>
    <actuator name="hip_motor_R1">
      <hardwareInterface>hardware_interface/EffortJointInterface</hardwareInterface>
      <mechanicalReduction>1.0</mechanicalReduction>
      <motorTorqueConstant>1.0</motorTorqueConstant>
    </actuator>
  </transmission>
  <transmission name="knee_transmission_R1">
    <type>transmission_interface/SimpleTransmission</type>
    <joint name="knee_joint_R1">
      <hardwareInterface>hardware_interface/EffortJointInterface</hardwareInterface>
    </joint>
    <actuator name="knee_motor_R1">
      <hardwareInterface>hardware_interface/EffortJointInterface</hardwareInterface>
      <mechanicalReduction>1.0</mechanicalReduction>
      <motorTorqueConstant>1.0</motorTorqueConstant>
    </actuator>
  </transmission>
  <!-- abad -->
  <joint name="abad_joint_R2" type="revolute">
    <parent link="base_link"/>
    <child link="abad_R2"/>
    <origin rpy="0 0 0" xyz="-0.149 -0.066 0.0"/>
    <axis xyz="1 0 0"/>
    <dynamics damping="0.8" friction="0"/>
    <limit effort="2000" lower="2.6179938779914944" upper="-2.6179938779914944" velocity="10.6"/>
  </joint>
  <link name="abad_R2">
    <visual>
      <origin rpy="1.57 0 4.71" xyz="0.046 0.0 0.0"/>
      <geometry>
        <mesh filename="package://walkerbro_sim/urdf/meshes/joint1.stl" scale="1 1 1"/>
      </geometry>
      <material name="white_blue"/>
    </visual>
    <collision>
      <origin rpy="1.57 0 4.71" xyz="0.046 0.0 0.0"/>
      <geometry>
        <mesh filename="package://walkerbro_sim/urdf/meshes/joint1.stl" scale="1 1 1"/>
      </geometry>
    </collision>
    <inertial>
      <origin rpy="0 0 1.57" xyz="-0.00654 -1.8e-05 0.047843"/>
      <mass value="0.301"/>
      <inertia ixx="0.000184443" ixy="-1.02e-07" ixz="-3.776e-06" iyy="0.000166614" iyz="-1e-08" izz="9.0598e-05"/>
    </inertial>
  </link>
  <!-- Hip-->
  <joint name="hip_joint_R2" type="revolute">
    <parent link="abad_R2"/>
    <child link="hip_R2"/>
    <origin rpy="0.0 0.0 0.0" xyz="0.0 -0.09885 0.0"/>
    <axis xyz="0 1 0"/>
    <dynamics damping="0.8" friction="0"/>
    <limit effort="2000" lower="2.6179938779914944" upper="-2.6179938779914944" velocity="10.6"/>
  </joint>
  <link name="hip_R2">
    <visual>
      <origin rpy="1.57 1.57 0.0" xyz="0.0 0.08835 0.0"/>
      <geometry>
        <mesh filename="package://walkerbro_sim/urdf/meshes/joint2.stl" scale="1 1 1"/>
      </geometry>
      <material name="silver"/>
    </visual>
    <collision>
      <origin rpy="1.57 1.57 0.0" xyz="0.0 0.08835 0.0"/>
      <geometry>
        <mesh filename="package://walkerbro_sim/urdf/meshes/joint2.stl" scale="1 1 1"/>
      </geometry>
    </collision>
    <inertial>
      <origin rpy="1.57 1.57 0.0" xyz="0.0 0.08835 0.0"/>
      <mass value="0.503"/>
      <inertia ixx="0.00027565" ixy="1.96e-07" ixz="-0.000196226" iyy="0.001115802" iyz="4.8e-08" izz="0.001123233"/>
    </inertial>
  </link>
  <!-- Knee -->
  <joint name="knee_joint_R2" type="revolute">
    <parent link="hip_R2"/>
    <child link="knee_R2"/>
    <origin rpy="0.0 0 0.0" xyz="0.0 0.0 -0.104"/>
    <axis xyz="0 1 0"/>
    <dynamics damping="0.8" friction="0"/>
    <limit effort="2000" lower="2.6179938779914944" upper="-2.6179938779914944" velocity="10.6"/>
  </joint>
  <link name="knee_R2">
    <visual>
      <origin rpy="1.57 1.57 0.0" xyz="0.0 0.012 0.0"/>
      <geometry>
        <mesh filename="package://walkerbro_sim/urdf/meshes/joint3.stl" scale="1 1 1"/>
      </geometry>
      <material name="white_blue"/>
    </visual>
    <collision>
      <origin rpy="1.57 1.57 0.0" xyz="0.0 0.012 0.0"/>
      <geometry>
        <mesh filename="package://walkerbro_sim/urdf/meshes/joint3.stl" scale="1 1 1"/>
      </geometry>
    </collision>
    <inertial>
      <origin rpy="0 0 0" xyz="0.043034 0.0 0.008988"/>
      <mass value="0.044"/>
      <inertia ixx="3.607e-06" ixy="0.0" ixz="-5.707e-06" iyy="0.000115918" iyz="0.0" izz="0.000115863"/>
    </inertial>
  </link>
  <!-- End Effector-->
  <joint name="ef_joint_R2" type="fixed">
    <parent link="knee_R2"/>
    <child link="ef_R2"/>
    <origin xyz="0 0 -0.1125"/>
  </joint>
  <link name="ef_R2"/>
  <!-- Define actuators -->
  <transmission name="abad_transmission_R2">
    <type>transmission_interface/SimpleTransmission</type>
    <joint name="abad_joint_R2">
      <hardwareInterface>hardware_interface/EffortJointInterface</hardwareInterface>
    </joint>
    <actuator name="soulder_motor_R2">
      <hardwareInterface>hardware_interface/EffortJointInterface</hardwareInterface>
      <mechanicalReduction>1.0</mechanicalReduction>
      <motorTorqueConstant>1.0</motorTorqueConstant>
    </actuator>
  </transmission>
  <transmission name="hip_transmission_R2">
    <type>transmission_interface/SimpleTransmission</type>
    <joint name="hip_joint_R2">
      <hardwareInterface>hardware_interface/EffortJointInterface</hardwareInterface>
    </joint>
    <actuator name="hip_motor_R2">
      <hardwareInterface>hardware_interface/EffortJointInterface</hardwareInterface>
      <mechanicalReduction>1.0</mechanicalReduction>
      <motorTorqueConstant>1.0</motorTorqueConstant>
    </actuator>
  </transmission>
  <transmission name="knee_transmission_R2">
    <type>transmission_interface/SimpleTransmission</type>
    <joint name="knee_joint_R2">
      <hardwareInterface>hardware_interface/EffortJointInterface</hardwareInterface>
    </joint>
    <actuator name="knee_motor_R2">
      <hardwareInterface>hardware_interface/EffortJointInterface</hardwareInterface>
      <mechanicalReduction>1.0</mechanicalReduction>
      <motorTorqueConstant>1.0</motorTorqueConstant>
    </actuator>
  </transmission>
  <!-- abad -->
  <joint name="abad_joint_L1" type="revolute">
    <parent link="base_link"/>
    <child link="abad_L1"/>
    <origin rpy="0 0 0" xyz="0.149 0.066 0.0"/>
    <axis xyz="1 0 0"/>
    <dynamics damping="0.8" friction="0"/>
    <limit effort="2000" lower="2.6179938779914944" upper="-2.6179938779914944" velocity="10.6"/>
  </joint>
  <link name="abad_L1">
    <visual>
      <origin rpy="1.57 0 1.57" xyz="-0.046 0.0 0.0"/>
      <geometry>
        <mesh filename="package://walkerbro_sim/urdf/meshes/joint1.stl" scale="1 1 1"/>
      </geometry>
      <material name="white_blue"/>
    </visual>
    <collision>
      <origin rpy="1.57 0 1.57" xyz="-0.046 0.0 0.0"/>
      <geometry>
        <mesh filename="package://walkerbro_sim/urdf/meshes/joint1.stl" scale="1 1 1"/>
      </geometry>
    </collision>
    <inertial>
      <origin rpy="0 0 1.57" xyz="-0.00654 -1.8e-05 0.047843"/>
      <mass value="0.301"/>
      <inertia ixx="0.000184443" ixy="-1.02e-07" ixz="-3.776e-06" iyy="0.000166614" iyz="-1e-08" izz="9.0598e-05"/>
    </inertial>
  </link>
  <!-- Hip-->
  <joint name="hip_joint_L1" type="revolute">
    <parent link="abad_L1"/>
    <child link="hip_L1"/>
    <origin rpy="0.0 0.0 0.0" xyz="0.0 0.09885 0.0"/>
    <axis xyz="0 1 0"/>
    <dynamics damping="0.8" friction="0"/>
    <limit effort="2000" lower="2.6179938779914944" upper="-2.6179938779914944" velocity="10.6"/>
  </joint>
  <link name="hip_L1">
    <visual>
      <origin rpy="-1.57 1.57 0.0" xyz="0.0 -0.08835 0.0"/>
      <geometry>
        <mesh filename="package://walkerbro_sim/urdf/meshes/joint2.stl" scale="1 1 1"/>
      </geometry>
      <material name="silver"/>
    </visual>
    <collision>
      <origin rpy="-1.57 1.57 0.0" xyz="0.0 -0.08835 0.0"/>
      <geometry>
        <mesh filename="package://walkerbro_sim/urdf/meshes/joint2.stl" scale="1 1 1"/>
      </geometry>
    </collision>
    <inertial>
      <origin rpy="0 0 0" xyz="0.025834 -5e-06 0.046911"/>
      <mass value="0.503"/>
      <inertia ixx="0.00027565" ixy="1.96e-07" ixz="-0.000196226" iyy="0.001115802" iyz="4.8e-08" izz="0.001123233"/>
    </inertial>
  </link>
  <!-- Knee -->
  <joint name="knee_joint_L1" type="revolute">
    <parent link="hip_L1"/>
    <child link="knee_L1"/>
    <origin rpy="0.0 0 0.0" xyz="0.0 0.0 -0.104"/>
    <axis xyz="0 1 0"/>
    <dynamics damping="0.8" friction="0"/>
    <limit effort="2000" lower="2.6179938779914944" upper="-2.6179938779914944" velocity="10.6"/>
  </joint>
  <link name="knee_L1">
    <visual>
      <origin rpy="-1.57 1.57 0.0" xyz="0.0 -0.012 0.0"/>
      <geometry>
        <mesh filename="package://walkerbro_sim/urdf/meshes/joint3.stl" scale="1 1 1"/>
      </geometry>
      <material name="white_blue"/>
    </visual>
    <collision>
      <origin rpy="-1.57 1.57 0.0" xyz="0.0 -0.012 0.0"/>
      <geometry>
        <mesh filename="package://walkerbro_sim/urdf/meshes/joint3.stl" scale="1 1 1"/>
      </geometry>
    </collision>
    <inertial>
      <origin rpy="0 0 0" xyz="0.043034 0.0 0.008988"/>
      <mass value="0.044"/>
      <inertia ixx="3.607e-06" ixy="0.0" ixz="-5.707e-06" iyy="0.000115918" iyz="0.0" izz="0.000115863"/>
    </inertial>
  </link>
  <!-- End Effector-->
  <joint name="ef_joint_L1" type="fixed">
    <parent link="knee_L1"/>
    <child link="ef_L1"/>
    <origin xyz="0 0 -0.1125"/>
  </joint>
  <link name="ef_L1"/>
  <!-- Define actuators -->
  <transmission name="abad_transmission_L1">
    <type>transmission_interface/SimpleTransmission</type>
    <joint name="abad_joint_L1">
      <hardwareInterface>hardware_interface/EffortJointInterface</hardwareInterface>
    </joint>
    <actuator name="soulder_motor_L1">
      <hardwareInterface>hardware_interface/EffortJointInterface</hardwareInterface>
      <mechanicalReduction>1.0</mechanicalReduction>
      <motorTorqueConstant>1.0</motorTorqueConstant>
    </actuator>
  </transmission>
  <transmission name="hip_transmission_L1">
    <type>transmission_interface/SimpleTransmission</type>
    <joint name="hip_joint_L1">
      <hardwareInterface>hardware_interface/EffortJointInterface</hardwareInterface>
    </joint>
    <actuator name="hip_motor_L1">
      <hardwareInterface>hardware_interface/EffortJointInterface</hardwareInterface>
      <mechanicalReduction>1.0</mechanicalReduction>
      <motorTorqueConstant>1.0</motorTorqueConstant>
    </actuator>
  </transmission>
  <transmission name="knee_transmission_L1">
    <type>transmission_interface/SimpleTransmission</type>
    <joint name="knee_joint_L1">
      <hardwareInterface>hardware_interface/EffortJointInterface</hardwareInterface>
    </joint>
    <actuator name="knee_motor_L1">
      <hardwareInterface>hardware_interface/EffortJointInterface</hardwareInterface>
      <mechanicalReduction>1.0</mechanicalReduction>
      <motorTorqueConstant>1.0</motorTorqueConstant>
    </actuator>
  </transmission>
  <!-- abad -->
  <joint name="abad_joint_L2" type="revolute">
    <parent link="base_link"/>
    <child link="abad_L2"/>
    <origin rpy="0 0 0" xyz="-0.149 0.066 0.0"/>
    <axis xyz="1 0 0"/>
    <dynamics damping="0.8" friction="0"/>
    <limit effort="2000" lower="2.6179938779914944" upper="-2.6179938779914944" velocity="10.6"/>
  </joint>
  <link name="abad_L2">
    <visual>
      <origin rpy="1.57 3.14 4.71" xyz="0.046 0.0 0.0"/>
      <geometry>
        <mesh filename="package://walkerbro_sim/urdf/meshes/joint1.stl" scale="1 1 1"/>
      </geometry>
      <material name="white_blue"/>
    </visual>
    <collision>
      <origin rpy="1.57 3.14 4.71" xyz="0.046 0.0 0.0"/>
      <geometry>
        <mesh filename="package://walkerbro_sim/urdf/meshes/joint1.stl" scale="1 1 1"/>
      </geometry>
    </collision>
    <inertial>
      <origin rpy="1.57 3.14 4.71" xyz="0.046 0.0 0.0"/>
      <mass value="0.301"/>
      <inertia ixx="0.000184443" ixy="-1.02e-07" ixz="-3.776e-06" iyy="0.000166614" iyz="-1e-08" izz="9.0598e-05"/>
    </inertial>
  </link>
  <!-- Hip-->
  <joint name="hip_joint_L2" type="revolute">
    <parent link="abad_L2"/>
    <child link="hip_L2"/>
    <origin rpy="0.0 0.0 0.0" xyz="0.0 0.09885 0.0"/>
    <axis xyz="0 1 0"/>
    <dynamics damping="0.8" friction="0"/>
    <limit effort="2000" lower="2.6179938779914944" upper="-2.6179938779914944" velocity="10.6"/>
  </joint>
  <link name="hip_L2">
    <visual>
      <origin rpy="-1.57 1.57 0.0" xyz="0.0 -0.08835 0.0"/>
      <geometry>
        <mesh filename="package://walkerbro_sim/urdf/meshes/joint2.stl" scale="1 1 1"/>
      </geometry>
      <material name="silver"/>
    </visual>
    <collision>
      <origin rpy="-1.57 1.57 0.0" xyz="0.0 -0.08835 0.0"/>
      <geometry>
        <mesh filename="package://walkerbro_sim/urdf/meshes/joint2.stl" scale="1 1 1"/>
      </geometry>
    </collision>
    <inertial>
      <origin rpy="-1.57 1.57 0.0" xyz="0.0 -0.08835 0.0"/>
      <mass value="0.503"/>
      <inertia ixx="0.00027565" ixy="1.96e-07" ixz="-0.000196226" iyy="0.001115802" iyz="4.8e-08" izz="0.001123233"/>
    </inertial>
  </link>
  <!-- Knee -->
  <joint name="knee_joint_L2" type="revolute">
    <parent link="hip_L2"/>
    <child link="knee_L2"/>
    <origin rpy="0.0 0 0.0" xyz="0.0 0.0 -0.104"/>
    <axis xyz="0 1 0"/>
    <dynamics damping="0.8" friction="0"/>
    <limit effort="2000" lower="2.6179938779914944" upper="-2.6179938779914944" velocity="10.6"/>
  </joint>
  <link name="knee_L2">
    <visual>
      <origin rpy="-1.57 1.57 0.0" xyz="0.0 -0.012 0.0"/>
      <geometry>
        <mesh filename="package://walkerbro_sim/urdf/meshes/joint3.stl" scale="1 1 1"/>
      </geometry>
      <material name="white_blue"/>
    </visual>
    <collision>
      <origin rpy="-1.57 1.57 0.0" xyz="0.0 -0.012 0.0"/>
      <geometry>
        <mesh filename="package://walkerbro_sim/urdf/meshes/joint3.stl" scale="1 1 1"/>
      </geometry>
    </collision>
    <inertial>
      <origin rpy="-1.57 1.57 0.0" xyz="0.0 -0.012 0.0"/>
      <mass value="0.044"/>
      <inertia ixx="3.607e-06" ixy="0.0" ixz="-5.707e-06" iyy="0.000115918" iyz="0.0" izz="0.000115863"/>
    </inertial>
  </link>
  <!-- End Effector-->
  <joint name="ef_joint_L2" type="fixed">
    <parent link="knee_L2"/>
    <child link="ef_L2"/>
    <origin xyz="0 0 -0.1125"/>
  </joint>
  <link name="ef_L2"/>
  <!-- Define actuators -->
  <transmission name="abad_transmission_L2">
    <type>transmission_interface/SimpleTransmission</type>
    <joint name="abad_joint_L2">
      <hardwareInterface>hardware_interface/EffortJointInterface</hardwareInterface>
    </joint>
    <actuator name="soulder_motor_L2">
      <hardwareInterface>hardware_interface/EffortJointInterface</hardwareInterface>
      <mechanicalReduction>1.0</mechanicalReduction>
      <motorTorqueConstant>1.0</motorTorqueConstant>
    </actuator>
  </transmission>
  <transmission name="hip_transmission_L2">
    <type>transmission_interface/SimpleTransmission</type>
    <joint name="hip_joint_L2">
      <hardwareInterface>hardware_interface/EffortJointInterface</hardwareInterface>
    </joint>
    <actuator name="hip_motor_L2">
      <hardwareInterface>hardware_interface/EffortJointInterface</hardwareInterface>
      <mechanicalReduction>1.0</mechanicalReduction>
      <motorTorqueConstant>1.0</motorTorqueConstant>
    </actuator>
  </transmission>
  <transmission name="knee_transmission_L2">
    <type>transmission_interface/SimpleTransmission</type>
    <joint name="knee_joint_L2">
      <hardwareInterface>hardware_interface/EffortJointInterface</hardwareInterface>
    </joint>
    <actuator name="knee_motor_L2">
      <hardwareInterface>hardware_interface/EffortJointInterface</hardwareInterface>
      <mechanicalReduction>1.0</mechanicalReduction>
      <motorTorqueConstant>1.0</motorTorqueConstant>
    </actuator>
  </transmission>
  <!-- <xacro:sensor_d435 name="camera" topics_ns="camera" parent="base_link" publish_pointcloud="true">
    <origin rpy="0 0 0" xyz="0.238 0.0 0.0"/>
  </xacro:sensor_d435>  -->
  <joint name="camera_joint" type="fixed">
    <origin rpy="0 0 0" xyz="0.238 0.0 0.0"/>
    <parent link="base_link"/>
    <child link="camera_frame"/>
  </joint>
  <link name="camera_frame"/>
  <material name="scan_plastic">
    <color rgba="0.2 0.2 0.2 1"/>
  </material>
  <joint name="scan_joint" type="fixed">
    <!-- <origin rpy="0 0 0" xyz="0.0 0.0 0.25"/> -->
    <origin rpy="0 0 0" xyz="-0.15 0.0 0.115"/>
    <parent link="base_link"/>
    <child link="scan_frame"/>
  </joint>
  <link name="scan_frame">
    <inertial>
      <mass value="0.270"/>
      <origin rpy="0 0 0" xyz="0 0 0"/>
      <inertia ixx="2.632e-4" ixy="0" ixz="0" iyy="2.632e-4" iyz="0" izz="1.62e-4"/>
    </inertial>
    <visual>
      <origin rpy="0 0 0" xyz="0 0 0"/>
      <geometry>
        <mesh filename="package://walkerbro_sim/urdf/meshes/rplidar_a1.stl"/>
      </geometry>
      <material name="scan_plastic"/>
    </visual>
    <collision>
      <origin rpy="0 0 0" xyz="0 0 -0.0115"/>
      <geometry>
        <box size="0.058 0.058 0.087"/>
        <!--<mesh filename="package://hector_sensors_description/meshes/${name}_utm30lx/${name}_utm_30lx.stl"/>-->
      </geometry>
    </collision>
  </link>
  <gazebo reference="scan_frame">
    <sensor name="scan" type="ray">
      <always_on>true</always_on>
      <update_rate>30</update_rate>
      <pose>0 0 0 0 0 0</pose>
      <visualize>false</visualize>
      <ray>
        <scan>
          <horizontal>
            <samples>1040</samples>
            <resolution>1</resolution>
            <min_angle>2.26892802759</min_angle>
            <max_angle>-2.26892802759</max_angle>
          </horizontal>
        </scan>
        <range>
          <min>0.2</min>
          <max>30.0</max>
          <resolution>0.01</resolution>
        </range>
        <noise>
          <type>gaussian</type>
          <mean>0.0</mean>
          <stddev>0.004</stddev>
        </noise>
      </ray>
      <plugin filename="libgazebo_ros_laser.so" name="gazebo_ros_hokuyo_controller">
        <topicName>scan</topicName>
        <frameName>hokuyo_frame</frameName>
      </plugin>
    </sensor>
  </gazebo>
  <link name="imu_link">
    <inertial>
      <mass value="0.001"/>
      <origin rpy="0 0 0" xyz="0 0 0"/>
      <inertia ixx="1e-09" ixy="0.0" ixz="0.0" iyy="1e-09" iyz="0.0" izz="1e-09"/>
    </inertial>
  </link>
  <joint name="imu_joint" type="fixed">
    <parent link="base_link"/>
    <child link="imu_link"/>
  </joint>
</robot>

